Workbook

Sheet Summary Dashboard
A1: Tekton Platform & Agentic Builder - QA Test Suite
A2: Interactive Manual QA Dashboard — Live Dynamic Formulas Linked Across All Page Sheets
A4: TOTAL TEST CASES | C4: PASSED | D4: FAILED | E4: UNKNOWN / UNTESTED | G4: OVERALL % SUCCESS
A5: =C26 -> 180 | C5: =D26 -> 0 | D5: =E26 -> 0 | E5: =F26 -> 180 | G5: =IF((D26+E26)>0, D26/(D26+E26), 0) -> 0
A7: Test Execution Breakdown by Page & Feature (Formulas Connected to Page Sheets)
A8: Feature / Page Area | B8: Target Route | C8: Total Test Cases | D8: Passed | E8: Failed | F8: Unknown / Untested | G8: % Success (Pass Rate) | H8: Primary Scope / Capabilities Verified
A9: Agentic Builder | B9: #/new | C9: =COUNTIF('Agentic Builder'!G2:G21, "<>") -> 20 | D9: =COUNTIF('Agentic Builder'!G2:G21, "Pass") -> 0 | E9: =COUNTIF('Agentic Builder'!G2:G21, "Fail") -> 0 | F9: =COUNTIF('Agentic Builder'!G2:G21, "Unknown") -> 20 | G9: =IF((D9+E9)>0, D9/(D9+E9), 0) -> 0 | H9: Natural language editing, URL crawl, PDF/OCR vision extraction, conflict reconciliation, grounding, undo
A10: Home | B10: #/ | C10: =COUNTIF(Home!G2:G11, "<>") -> 10 | D10: =COUNTIF(Home!G2:G11, "Pass") -> 0 | E10: =COUNTIF(Home!G2:G11, "Fail") -> 0 | F10: =COUNTIF(Home!G2:G11, "Unknown") -> 10 | G10: =IF((D10+E10)>0, D10/(D10+E10), 0) -> 0 | H10: Hero CTAs, feature navigation, giving progress bar, ministries list, recent sermons, contact block
A11: Plan Your Visit | B11: #/guests/plan | C11: =COUNTIF('Plan Your Visit'!G2:G11, "<>") -> 10 | D11: =COUNTIF('Plan Your Visit'!G2:G11, "Pass") -> 0 | E11: =COUNTIF('Plan Your Visit'!G2:G11, "Fail") -> 0 | F11: =COUNTIF('Plan Your Visit'!G2:G11, "Unknown") -> 10 | G11: =IF((D11+E11)>0, D11/(D11+E11), 0) -> 0 | H11: RSVP form submission, validation, campus parking map selection, arrival flow, FAQ accordion
A12: Welcome Team | B12: #/guests/welcome | C12: =COUNTIF('Welcome Team'!G2:G11, "<>") -> 10 | D12: =COUNTIF('Welcome Team'!G2:G11, "Pass") -> 0 | E12: =COUNTIF('Welcome Team'!G2:G11, "Fail") -> 0 | F12: =COUNTIF('Welcome Team'!G2:G11, "Unknown") -> 10 | G12: =IF((D12+E12)>0, D12/(D12+E12), 0) -> 0 | H12: Staff-only arrival queue, host claiming, notifications, arrival time metrics, live polling
A13: Serve | B13: #/serve | C13: =COUNTIF(Serve!G2:G11, "<>") -> 10 | D13: =COUNTIF(Serve!G2:G11, "Pass") -> 0 | E13: =COUNTIF(Serve!G2:G11, "Fail") -> 0 | F13: =COUNTIF(Serve!G2:G11, "Unknown") -> 10 | G13: =IF((D13+E13)>0, D13/(D13+E13), 0) -> 0 | H13: Keyword search, urgent needs filter, AI matching recommendations, bookmarking, staff request queue
A14: Sermon Notes | B14: #/notes | C14: =COUNTIF('Sermon Notes'!G2:G11, "<>") -> 10 | D14: =COUNTIF('Sermon Notes'!G2:G11, "Pass") -> 0 | E14: =COUNTIF('Sermon Notes'!G2:G11, "Fail") -> 0 | F14: =COUNTIF('Sermon Notes'!G2:G11, "Unknown") -> 10 | G14: =IF((D14+E14)>0, D14/(D14+E14), 0) -> 0 | H14: Transcript browsing, AI sermon Q&A with timestamps, media playback sync, YouVersion verse lookup, upload
A15: Calendar | B15: #/calendar | C15: =COUNTIF(Calendar!G2:G11, "<>") -> 10 | D15: =COUNTIF(Calendar!G2:G11, "Pass") -> 0 | E15: =COUNTIF(Calendar!G2:G11, "Fail") -> 0 | F15: =COUNTIF(Calendar!G2:G11, "Unknown") -> 10 | G15: =IF((D15+E15)>0, D15/(D15+E15), 0) -> 0 | H15: Monthly grid & list views, category filter, keyword search, month navigation, staff event CRUD
A16: Give | B16: #/give | C16: =COUNTIF(Give!G2:G11, "<>") -> 10 | D16: =COUNTIF(Give!G2:G11, "Pass") -> 0 | E16: =COUNTIF(Give!G2:G11, "Fail") -> 0 | F16: =COUNTIF(Give!G2:G11, "Unknown") -> 10 | G16: =IF((D16+E16)>0, D16/(D16+E16), 0) -> 0 | H16: Donation presets, custom amounts, fund selector, recurring monthly toggle, Stripe checkout, trips
A17: Prayer Map | B17: #/prayer | C17: =COUNTIF('Prayer Map'!G2:G11, "<>") -> 10 | D17: =COUNTIF('Prayer Map'!G2:G11, "Pass") -> 0 | E17: =COUNTIF('Prayer Map'!G2:G11, "Fail") -> 0 | F17: =COUNTIF('Prayer Map'!G2:G11, "Unknown") -> 10 | G17: =IF((D17+E17)>0, D17/(D17+E17), 0) -> 0 | H17: Leaflet world map, country prayer beacons, verified news pins, sensitive country anonymization
A18: About - Our Story | B18: #/about | C18: =COUNTIF('About - Our Story'!G2:G11, "<>") -> 10 | D18: =COUNTIF('About - Our Story'!G2:G11, "Pass") -> 0 | E18: =COUNTIF('About - Our Story'!G2:G11, "Fail") -> 0 | F18: =COUNTIF('About - Our Story'!G2:G11, "Unknown") -> 10 | G18: =IF((D18+E18)>0, D18/(D18+E18), 0) -> 0 | H18: Mission statement, narrative story, core value cards, visit block, provenance quote inspect
A19: About - Beliefs | B19: #/about/beliefs | C19: =COUNTIF('About - Beliefs'!G2:G11, "<>") -> 10 | D19: =COUNTIF('About - Beliefs'!G2:G11, "Pass") -> 0 | E19: =COUNTIF('About - Beliefs'!G2:G11, "Fail") -> 0 | F19: =COUNTIF('About - Beliefs'!G2:G11, "Unknown") -> 10 | G19: =IF((D19+E19)>0, D19/(D19+E19), 0) -> 0 | H19: Doctrinal preamble, numbered belief articles, custom imported beliefs, sub-navigation
A20: About - News | B20: #/about/news | C20: =COUNTIF('About - News'!G2:G11, "<>") -> 10 | D20: =COUNTIF('About - News'!G2:G11, "Pass") -> 0 | E20: =COUNTIF('About - News'!G2:G11, "Fail") -> 0 | F20: =COUNTIF('About - News'!G2:G11, "Unknown") -> 10 | G20: =IF((D20+E20)>0, D20/(D20+E20), 0) -> 0 | H20: Updates vs articles filter, taxonomy tags, AI 3-bullet summary, staff post publishing & moderation
A21: About - Directory | B21: #/about/directory | C21: =COUNTIF('About - Directory'!G2:G11, "<>") -> 10 | D21: =COUNTIF('About - Directory'!G2:G11, "Pass") -> 0 | E21: =COUNTIF('About - Directory'!G2:G11, "Fail") -> 0 | F21: =COUNTIF('About - Directory'!G2:G11, "Unknown") -> 10 | G21: =IF((D21+E21)>0, D21/(D21+E21), 0) -> 0 | H21: Staff search, role filtering, click-to-call, click-to-email, office hours, ministry leaders
A22: About - Connect | B22: #/about/connect | C22: =COUNTIF('About - Connect'!G2:G11, "<>") -> 10 | D22: =COUNTIF('About - Connect'!G2:G11, "Pass") -> 0 | E22: =COUNTIF('About - Connect'!G2:G11, "Fail") -> 0 | F22: =COUNTIF('About - Connect'!G2:G11, "Unknown") -> 10 | G22: =IF((D22+E22)>0, D22/(D22+E22), 0) -> 0 | H22: Next step pathways, small groups directory, imported external forms, email inquiry mailto generator
A23: Admin - Staff | B23: #/staff | C23: =COUNTIF('Admin - Staff'!G2:G11, "<>") -> 10 | D23: =COUNTIF('Admin - Staff'!G2:G11, "Pass") -> 0 | E23: =COUNTIF('Admin - Staff'!G2:G11, "Fail") -> 0 | F23: =COUNTIF('Admin - Staff'!G2:G11, "Unknown") -> 10 | G23: =IF((D23+E23)>0, D23/(D23+E23), 0) -> 0 | H23: Staff sign-in, Stripe onboarding, funds management, trip applications review, donor gifts ledger
A24: Admin - Setup | B24: #/setup | C24: =COUNTIF('Admin - Setup'!G2:G11, "<>") -> 10 | D24: =COUNTIF('Admin - Setup'!G2:G11, "Pass") -> 0 | E24: =COUNTIF('Admin - Setup'!G2:G11, "Fail") -> 0 | F24: =COUNTIF('Admin - Setup'!G2:G11, "Unknown") -> 10 | G24: =IF((D24+E24)>0, D24/(D24+E24), 0) -> 0 | H24: Church branding, contact details, service times management, FAQs CRUD, ministries provisioning
A25: Sitewide Chat | B25: Global Widget | C25: =COUNTIF('Sitewide Chat'!G2:G11, "<>") -> 10 | D25: =COUNTIF('Sitewide Chat'!G2:G11, "Pass") -> 0 | E25: =COUNTIF('Sitewide Chat'!G2:G11, "Fail") -> 0 | F25: =COUNTIF('Sitewide Chat'!G2:G11, "Unknown") -> 10 | G25: =IF((D25+E25)>0, D25/(D25+E25), 0) -> 0 | H25: Chat launcher, starter pills, scheduled event queries, volunteer inquiry, prayer request handoff
A26: Suite Total / Rollup | B26: All 17 Areas | C26: =SUM(C9:C25) -> 180 | D26: =SUM(D9:D25) -> 0 | E26: =SUM(E9:E25) -> 0 | F26: =SUM(F9:F25) -> 180 | G26: =IF((D26+E26)>0, D26/(D26+E26), 0) -> 0 | H26: Dynamic rollup tracking user-tested execution progress across all 17 page sheets

Sheet All Test Cases
A1: Name of Test Case | B1: Category | C1: Name of Page | D1: Action to Take | E1: Expected Outcome | F1: Outcome/Result | G1: Pass/Fail
A2: ='Agentic Builder'!A2 -> Ask AI to change pastor name | B2: ='Agentic Builder'!B2 -> Natural Language Editing | C2: ='Agentic Builder'!C2 -> Builder | D2: ='Agentic Builder'!D2 -> In review screen or preview banner, enter 'Change pastor name to Pastor John Mark' into Tekton edit box and click 'Change it'. | E2: ='Agentic Builder'!E2 -> Agent identifies lead pastor in staff collection, updates name to 'Pastor John Mark', confirms with 'Changed pastor to Pastor John Mark', and increments undo count. | F2: ='Agentic Builder'!F2 | G2: ='Agentic Builder'!G2 -> Unknown
A3: ='Agentic Builder'!A3 -> Reorder sections: Put service times above ministries | B3: ='Agentic Builder'!B3 -> Natural Language Layout | C3: ='Agentic Builder'!C3 -> Builder | D3: ='Agentic Builder'!D3 -> Type 'Put service times above ministries' in Tekton edit box and click 'Change it'. | E3: ='Agentic Builder'!E3 -> Deterministic layout rule detects service_times and ministries on Home, moves service times before ministries, and confirms 'Moved Service times on Home above Ministries'. | F3: ='Agentic Builder'!F3 | G3: ='Agentic Builder'!G3 -> Unknown
A4: ='Agentic Builder'!A4 -> Hide specific ministry: Hide the youth ministry | B4: ='Agentic Builder'!B4 -> Natural Language Visibility | C4: ='Agentic Builder'!C4 -> Builder | D4: ='Agentic Builder'!D4 -> Type 'Hide the youth ministry' into Tekton edit input and click 'Change it'. | E4: ='Agentic Builder'!E4 -> Agent matches 'Youth Ministry' in ministries collection, sets include: false, and replies 'Left out Youth Ministry'. | F4: ='Agentic Builder'!F4 | G4: ='Agentic Builder'!G4 -> Unknown
A5: ='Agentic Builder'!A5 -> Move section to top: Move what to expect to the top | B5: ='Agentic Builder'!B5 -> Natural Language Layout | C5: ='Agentic Builder'!C5 -> Builder | D5: ='Agentic Builder'!D5 -> Type 'Move what to expect to the top' into Tekton edit input and click 'Change it'. | E5: ='Agentic Builder'!E5 -> Layout engine moves what_to_expect section on Plan your visit page to index 0 and replies 'Moved What to expect on Plan your visit to the top'. | F5: ='Agentic Builder'!F5 | G5: ='Agentic Builder'!G5 -> Unknown
A6: ='Agentic Builder'!A6 -> Update church phone number via plain text command | B6: ='Agentic Builder'!B6 -> Natural Language Detail Update | C6: ='Agentic Builder'!C6 -> Builder | D6: ='Agentic Builder'!D6 -> Type 'Change the phone number to (555) 019-9988' into Tekton edit input and click 'Change it'. | E6: ='Agentic Builder'!E6 -> Agent parses new phone format, validates number, updates church contact phone field, and replies 'Changed phone to (555) 019-9988'. | F6: ='Agentic Builder'!F6 | G6: ='Agentic Builder'!G6 -> Unknown
A7: ='Agentic Builder'!A7 -> Undo previous edit operation | B7: ='Agentic Builder'!B7 -> Revision Control | C7: ='Agentic Builder'!C7 -> Builder | D7: ='Agentic Builder'!D7 -> Click 'Undo' button after executing a section reordering or detail change. | E7: ='Agentic Builder'!E7 -> Restores previous draft snapshot state from undo stack, decrements undo count, and announces reversed changes. | F7: ='Agentic Builder'!F7 | G7: ='Agentic Builder'!G7 -> Unknown
A8: ='Agentic Builder'!A8 -> Import website from live URL (Happy path crawl) | B8: ='Agentic Builder'!B8 -> URL Crawl & Ingestion | C8: ='Agentic Builder'!C8 -> Builder | D8: ='Agentic Builder'!D8 -> Select 'Import a website', enter 'https://cedarhollow.example.org', and click 'Start import'. | E8: ='Agentic Builder'!E8 -> Crawler reads sitemap and top pages within robots.txt limits, extracts name, address, phone, email, and service times with 0 false conflicts, and transitions to review. | F8: ='Agentic Builder'!F8 | G8: ='Agentic Builder'!G8 -> Unknown
A9: ='Agentic Builder'!A9 -> Detect conflicting service times from messy site | B9: ='Agentic Builder'!B9 -> Conflict Detection | C9: ='Agentic Builder'!C9 -> Builder | D9: ='Agentic Builder'!D9 -> Import URL containing conflicting times: 'Sundays 9 & 11' on home page and 'Sunday 10:30am' on news post. | E9: ='Agentic Builder'!E9 -> Draft status transitions to clarifying; displays conflict question card showing both candidate times with verbatim source quotes and page links. | F9: ='Agentic Builder'!F9 | G9: ='Agentic Builder'!G9 -> Unknown
A10: ='Agentic Builder'!A10 -> Resolve service time conflict by picking candidate card | B10: ='Agentic Builder'!B10 -> Human Clarification Flow | C10: ='Agentic Builder'!C10 -> Builder | D10: ='Agentic Builder'!D10 -> On service times conflict card, click candidate 'Sunday 9:00 AM, Sunday 11:00 AM' and click 'Confirm answer'. | E10: ='Agentic Builder'!E10 -> Selected service times are locked into confirmed status with provenance attribution; builder advances to next question or review. | F10: ='Agentic Builder'!F10 | G10: ='Agentic Builder'!G10 -> Unknown
A11: ='Agentic Builder'!A11 -> Prompt for missing required address and accept manual input | B11: ='Agentic Builder'!B11 -> Gap Detection & Form Validation | C11: ='Agentic Builder'!C11 -> Builder | D11: ='Agentic Builder'!D11 -> When presented with 'We could not find street address', type '100 Faith Way, Springfield, IL 62701' into input and submit. | E11: ='Agentic Builder'!E11 -> Manual address entry is validated, saved to draft with confirmed status ('You confirmed this'), and question resolves. | F11: ='Agentic Builder'!F11 | G11: ='Agentic Builder'!G11 -> Unknown
A12: ='Agentic Builder'!A12 -> Ingest PDF church bulletin and extract facts | B12: ='Agentic Builder'!B12 -> Document Extraction - PDF | C12: ='Agentic Builder'!C12 -> Builder | D12: ='Agentic Builder'!D12 -> Select 'Upload files', drag and drop a 2 MB weekly church bulletin PDF containing service times and pastor bio, and click 'Read files'. | E12: ='Agentic Builder'!E12 -> Server parses PDF text streams, applies NLP regex patterns, extracts service times and staff items, and displays quotes referencing PDF filename. | F12: ='Agentic Builder'!F12 | G12: ='Agentic Builder'!G12 -> Unknown
A13: ='Agentic Builder'!A13 -> Ingest church flyer image via Vision AI OCR | B13: ='Agentic Builder'!B13 -> Multimodal Vision Extraction | C13: ='Agentic Builder'!C13 -> Builder | D13: ='Agentic Builder'!D13 -> Upload church flyer image (JPEG/PNG) displaying worship schedule and logo. | E13: ='Agentic Builder'!E13 -> Vision AI transcribes image text into machine-readable prose; rules parser extracts church schedule and logo reference. | F13: ='Agentic Builder'!F13 | G13: ='Agentic Builder'!G13 -> Unknown
... A21: ='Agentic Builder'!A21 -> Publish live production church without invite code | B21: ='Agentic Builder'!B21 -> Tenant Provisioning Guardrail | C21: ='Agentic Builder'!C21 -> Builder | D21: ='Agentic Builder'!D21 -> On preview screen, attempt to provision and deploy a new live church tenant without entering an invite code. | E21: ='Agentic Builder'!E21 -> System provisions new church tenant and deploys public domain. | F21: ='Agentic Builder'!F21 | G21: ='Agentic Builder'!G21 -> Unknown
A22: =Home!A2 -> Hero CTA: Find a place to serve button | B22: =Home!B2 -> Navigation & User Flow | C22: =Home!C2 -> Home | D22: =Home!D2 -> Click 'Find a place to serve' primary button on the hero banner. | E22: =Home!E2 -> Application navigates directly to '#/serve/find' volunteer matching page. | F22: =Home!F2 | G22: =Home!G2 -> Unknown
A23: =Home!A3 -> Hero CTA: Planning your first visit button | B23: =Home!B3 -> Navigation & User Flow | C23: =Home!C3 -> Home | D23: =Home!D3 -> Click 'Planning your first visit?' secondary button on the hero banner. | E23: =Home!E3 -> Application navigates directly to '#/guests/plan' first-time guest page. | F23: =Home!F3 | G23: =Home!G3 -> Unknown
A24: =Home!A4 -> Hero CTA: Ask Tekton chat launcher | B24: =Home!B4 -> AI Assistant Integration | C24: =Home!C4 -> Home | D24: =Home!D4 -> Click 'Ask Tekton' button with chat icon in the hero banner. | E24: =Home!E4 -> Sitewide chat assistant drawer slides open from right with greeting message. | F24: =Home!F4 | G24: =Home!G4 -> Unknown
A25: =Home!A5 -> Serve feature card navigation | B25: =Home!B5 -> Feature Card Routing | C25: =Home!C5 -> Home | D25: =Home!D5 -> Click 'Serve' feature card in the main features grid. | E25: =Home!E5 -> Navigates to '#/serve' ministries directory overview page. | F25: =Home!F5 | G25: =Home!G5 -> Unknown
A26: =Home!A6 -> Sermon Notes feature card navigation | B26: =Home!B6 -> Feature Card Routing | C26: =Home!C6 -> Home | D26: =Home!D6 -> Click 'Sermon Notes' feature card in the main features grid. | E26: =Home!E6 -> Navigates to '#/notes' sermon notes transcript archive. | F26: =Home!F6 | G26: =Home!G6 -> Unknown
A27: =Home!A7 -> Give feature card goal progress bar display | B27: =Home!B7 -> Fundraising Goal Tracking | C27: =Home!C7 -> Home | D27: =Home!D7 -> Inspect Give feature card when a church fund has an active fundraising goal. | E27: =Home!E7 -> Card displays fund name, raised amount, goal amount, and accurately styled visual percentage progress bar. | F27: =Home!F7 | G27: =Home!G7 -> Unknown
A28: =Home!A8 -> Get to know us directory quick button | B28: =Home!B8 -> Quick Links Navigation | C28: =Home!C8 -> Home | D28: =Home!D8 -> Click 'Contact directory' button in the 'Get to know us' section. | E28: =Home!E8 -> Navigates directly to '#/about/directory' staff contact listing. | F28: =Home!F8 | G28: =Home!G8 -> Unknown
A29: =Home!A9 -> Service times and address card rendering | B29: =Home!B9 -> Visitor Information | C29: =Home!C9 -> Home | D29: =Home!D9 -> Inspect 'Service times' block on the Home page. | E29: =Home!E9 -> Displays weekly gathering schedule (e.g. 'Sunday 9:00 AM & 11:00 AM') and church physical address with location pin icon. | F29: =Home!F9 | G29: =Home!G9 -> Unknown
A30: =Home!A10 -> Watch Live external link when livestream is unconfigured | B30: =Home!B10 -> Livestream Integration | C30: =Home!C10 -> Home | D30: =Home!D10 -> Click 'Watch live' hero action button when church has no active livestream URL configured. | E30: =Home!E10 -> Displays friendly popup indicating no active broadcast is currently streaming. | F30: =Home!F10 | G30: =Home!G10 -> Unknown
A31: =Home!A11 -> Hero about text rendering on new unconfigured church | B31: =Home!B11 -> Tenant Onboarding Display | C31: =Home!C11 -> Home | D31: =Home!D11 -> Open Home page for newly provisioned church with no about description provided. | E31: =Home!E11 -> Displays elegant onboarding prompt guiding visitors and staff to add story. | F31: =Home!F11 | G31: =Home!G11 -> Unknown
A32: ='Plan Your Visit'!A2 -> Submit guest visit RSVP registration form | B32: ='Plan Your Visit'!B2 -> Guest Registration Flow | C32: ='Plan Your Visit'!C2 -> Guests - Plan Your Visit | D32: ='Plan Your Visit'!D2 -> Fill in name 'Sarah Jenkins', contact 'sarah@example.org', select 'Sunday 9:00 AM', party size 3, and click 'Let us know you’re coming'. | E32: ='Plan Your Visit'!E2 -> Form submits to POST /api/visits, receives visit token, saves token to localStorage, and updates UI to registered state. | F32: ='Plan Your Visit'!F2 | G32: ='Plan Your Visit'!G2 -> Unknown
A33: ='Plan Your Visit'!A3 -> Validate required fields in visit registration | B33: ='Plan Your Visit'!B3 -> Form Validation | C33: ='Plan Your Visit'!C3 -> Guests - Plan Your Visit | D33: ='Plan Your Visit'!D3 -> Leave name and contact fields blank and click 'Let us know you’re coming'. | E33: ='Plan Your Visit'!E3 -> Browser displays HTML5 validation prompt on required name and contact inputs; submission is halted. | F33: ='Plan Your Visit'!F3 | G33: ='Plan Your Visit'!G3 -> Unknown
A34: ='Plan Your Visit'!A4 -> Select service time from dynamic dropdown | B34: ='Plan Your Visit'!B4 -> Form Interaction | C34: ='Plan Your Visit'!C4 -> Guests - Plan Your Visit | D34: ='Plan Your Visit'!D4 -> Click service time dropdown and select second gathering 'Sunday 11:00 AM'. | E34: ='Plan Your Visit'!E4 -> Selected service time state updates and is included in the visit payload. | F34: ='Plan Your Visit'!F4 | G34: ='Plan Your Visit'!G4 -> Unknown
A35: ='Plan Your Visit'!A5 -> Toggle 'I’d like someone to meet me' host checkbox | B35: ='Plan Your Visit'!B5 -> Hospitality Preferences | C35: ='Plan Your Visit'!C5 -> Guests - Plan Your Visit | D35: ='Plan Your Visit'!D5 -> Uncheck the 'I’d like someone to meet me at the front doors' checkbox. | E35: ='Plan Your Visit'!E5 -> wantsHost state sets to false; submitted visit payload reflects 'wants_host: false'. | F35: ='Plan Your Visit'!F5 | G35: ='Plan Your Visit'!G5 -> Unknown
A36: ='Plan Your Visit'!A6 -> Click 'I’m on my way' arrival notification button | B36: ='Plan Your Visit'!B6 -> Guest Arrival Flow | C36: ='Plan Your Visit'!C6 -> Guests - Plan Your Visit | D36: ='Plan Your Visit'!D6 -> On the confirmed visit card, click 'I’m on my way' button. | E36: ='Plan Your Visit'!E6 -> Visits API updates status to 'on_the_way'; welcome team queue receives live status update. | F36: ='Plan Your Visit'!F6 | G36: ='Plan Your Visit'!G6 -> Unknown
A37: ='Plan Your Visit'!A7 -> Click 'I have arrived' check-in button | B37: ='Plan Your Visit'!B7 -> Guest Arrival Flow | C37: ='Plan Your Visit'!C7 -> Guests - Plan Your Visit | D37: ='Plan Your Visit'!D7 -> On confirmed visit card, click 'I have arrived' button. | E37: ='Plan Your Visit'!E7 -> Visits API updates status to 'arrived'; triggers desktop notification on welcome team workstation. | F37: ='Plan Your Visit'!F7 | G37: ='Plan Your Visit'!G7 -> Unknown
A38: ='Plan Your Visit'!A8 -> Expand FAQ accordion to read answer | B38: ='Plan Your Visit'!B8 -> Content Disclosure | C38: ='Plan Your Visit'!C8 -> Guests - Plan Your Visit | D38: ='Plan Your Visit'!D8 -> Click on question 'What should I wear?' in the FAQ section. | E38: ='Plan Your Visit'!E8 -> Accordion item expands revealing helpful answer about casual attire. | F38: ='Plan Your Visit'!F8 | G38: ='Plan Your Visit'!G8 -> Unknown
A39: ='Plan Your Visit'!A9 -> Open Google Maps directions link | B39: ='Plan Your Visit'!B9 -> External Navigation | C39: ='Plan Your Visit'!C9 -> Guests - Plan Your Visit | D39: ='Plan Your Visit'!D9 -> Click 'Get directions' button next to the church address. | E39: ='Plan Your Visit'!E9 -> Opens Google Maps search query with church street address in new browser tab. | F39: ='Plan Your Visit'!F9 | G39: ='Plan Your Visit'!G9 -> Unknown
A40: ='Plan Your Visit'!A10 -> Interactive parking spot selection on mobile Safari touchscreens | B40: ='Plan Your Visit'!B10 -> Touchscreen Mapping | C40: ='Plan Your Visit'!C10 -> Guests - Plan Your Visit | D40: ='Plan Your Visit'!D10 -> Tap parking spot on campus SVG map using an iOS Safari mobile browser. | E40: ='Plan Your Visit'!E10 -> Spot highlights and selection binds to form payload. | F40: ='Plan Your Visit'!F10 | G40: ='Plan Your Visit'!G10 -> Unknown
A41: ='Plan Your Visit'!A11 -> Guest RSVP submission with international phone number format | B41: ='Plan Your Visit'!B11 -> Input Sanitization & Regex | C41: ='Plan Your Visit'!C11 -> Guests - Plan Your Visit | D41: ='Plan Your Visit'!D11 -> Enter international format contact number '+44 20 7946 0958' in RSVP contact field. | E41: ='Plan Your Visit'!E11 -> Validates international phone format and registers visit. | F41: ='Plan Your Visit'!F11 | G41: ='Plan Your Visit'!G11 -> Unknown
A42: ='Welcome Team'!A2 -> Block unauthorized visitor access to welcome queue | B42: ='Welcome Team'!B2 -> Access Control | C42: ='Welcome Team'!C2 -> Guests - Welcome Team | D42: ='Welcome Team'!D2 -> Navigate to '#/guests/welcome' as an unauthenticated public visitor. | E42: ='Welcome Team'!E2 -> Welcome queue is hidden; displays 'StaffOnly' notice prompting staff sign-in. | F42: ='Welcome Team'!F2 | G42: ='Welcome Team'!G2 -> Unknown
A43: ='Welcome Team'!A3 -> Display arrived guests queue for signed-in staff | B43: ='Welcome Team'!B3 -> Queue Visibility | C43: ='Welcome Team'!C3 -> Guests - Welcome Team | D43: ='Welcome Team'!D3 -> Sign in as staff and open '#/guests/welcome'. | E43: ='Welcome Team'!E3 -> Displays WelcomeQueue component showing waiting list and planned guests list. | F43: ='Welcome Team'!F3 | G43: ='Welcome Team'!G3 -> Unknown
A44: ='Welcome Team'!A4 -> Persist host staff name in local storage | B44: ='Welcome Team'!B4 -> Host Identity | C44: ='Welcome Team'!C4 -> Guests - Welcome Team | D44: ='Welcome Team'!D4 -> Type host name 'Brother David' into 'Your name' field and reload page. | E44: ='Welcome Team'!E4 -> Host name 'Brother David' is saved to localStorage and restored on reload. | F44: ='Welcome Team'!F4 | G44: ='Welcome Team'!G4 -> Unknown
A45: ='Welcome Team'!A5 -> Claim an arrived guest from waiting queue | B45: ='Welcome Team'!B5 -> Host Assignment | C45: ='Welcome Team'!C5 -> Guests - Welcome Team | D45: ='Welcome Team'!D5 -> Click 'I’ll meet them' button on a waiting guest card. | E45: ='Welcome Team'!E5 -> Calls POST /visits/:id/claim with hostName; marks guest as claimed by Brother David. | F45: ='Welcome Team'!F5 | G45: ='Welcome Team'!G5 -> Unknown
A46: ='Welcome Team'!A6 -> Dismiss welcomed guest from queue | B46: ='Welcome Team'!B6 -> Status Lifecycle | C46: ='Welcome Team'!C6 -> Guests - Welcome Team | D46: ='Welcome Team'!D6 -> Click 'Welcomed' checkmark button on a claimed guest card. | E46: ='Welcome Team'!E6 -> Calls PATCH /visits/:id with status 'welcomed'; removes guest from active waiting list. | F46: ='Welcome Team'!F6 | G46: ='Welcome Team'!G6 -> Unknown
A47: ='Welcome Team'!A7 -> Display accurate party size and host preference tags | B47: ='Welcome Team'!B7 -> Metadata Rendering | C47: ='Welcome Team'!C7 -> Guests - Welcome Team | D47: ='Welcome Team'!D7 -> Inspect waiting guest card for party of 4 who prefers not to be met. | E47: ='Welcome Team'!E7 -> Card displays 'Party of 4' badge and muted notice 'Prefers not to be met at door'. | F47: ='Welcome Team'!F7 | G47: ='Welcome Team'!G7 -> Unknown
...

Sheet Agentic Builder
A1: Name of Test Case | B1: Category | C1: Name of Page | D1: Action to Take | E1: Expected Outcome | F1: Outcome/Result | G1: Pass/Fail
A2: Ask AI to change pastor name | B2: Natural Language Editing | C2: Builder | D2: In review screen or preview banner, enter 'Change pastor name to Pastor John Mark' into Tekton edit box and click 'Change it'. | E2: Agent identifies lead pastor in staff collection, updates name to 'Pastor John Mark', confirms with 'Changed pastor to Pastor John Mark', and increments undo count. | G2: Unknown
A3: Reorder sections: Put service times above ministries | B3: Natural Language Layout | C3: Builder | D3: Type 'Put service times above ministries' in Tekton edit box and click 'Change it'. | E3: Deterministic layout rule detects service_times and ministries on Home, moves service times before ministries, and confirms 'Moved Service times on Home above Ministries'. | G3: Unknown
A4: Hide specific ministry: Hide the youth ministry | B4: Natural Language Visibility | C4: Builder | D4: Type 'Hide the youth ministry' into Tekton edit input and click 'Change it'. | E4: Agent matches 'Youth Ministry' in ministries collection, sets include: false, and replies 'Left out Youth Ministry'. | G4: Unknown
A5: Move section to top: Move what to expect to the top | B5: Natural Language Layout | C5: Builder | D5: Type 'Move what to expect to the top' into Tekton edit input and click 'Change it'. | E5: Layout engine moves what_to_expect section on Plan your visit page to index 0 and replies 'Moved What to expect on Plan your visit to the top'. | G5: Unknown
A6: Update church phone number via plain text command | B6: Natural Language Detail Update | C6: Builder | D6: Type 'Change the phone number to (555) 019-9988' into Tekton edit input and click 'Change it'. | E6: Agent parses new phone format, validates number, updates church contact phone field, and replies 'Changed phone to (555) 019-9988'. | G6: Unknown
A7: Undo previous edit operation | B7: Revision Control | C7: Builder | D7: Click 'Undo' button after executing a section reordering or detail change. | E7: Restores previous draft snapshot state from undo stack, decrements undo count, and announces reversed changes. | G7: Unknown
A8: Import website from live URL (Happy path crawl) | B8: URL Crawl & Ingestion | C8: Builder | D8: Select 'Import a website', enter 'https://cedarhollow.example.org', and click 'Start import'. | E8: Crawler reads sitemap and top pages within robots.txt limits, extracts name, address, phone, email, and service times with 0 false conflicts, and transitions to review. | G8: Unknown
A9: Detect conflicting service times from messy site | B9: Conflict Detection | C9: Builder | D9: Import URL containing conflicting times: 'Sundays 9 & 11' on home page and 'Sunday 10:30am' on news post. | E9: Draft status transitions to clarifying; displays conflict question card showing both candidate times with verbatim source quotes and page links. | G9: Unknown
A10: Resolve service time conflict by picking candidate card | B10: Human Clarification Flow | C10: Builder | D10: On service times conflict card, click candidate 'Sunday 9:00 AM, Sunday 11:00 AM' and click 'Confirm answer'. | E10: Selected service times are locked into confirmed status with provenance attribution; builder advances to next question or review. | G10: Unknown
A11: Prompt for missing required address and accept manual input | B11: Gap Detection & Form Validation | C11: Builder | D11: When presented with 'We could not find street address', type '100 Faith Way, Springfield, IL 62701' into input and submit. | E11: Manual address entry is validated, saved to draft with confirmed status ('You confirmed this'), and question resolves. | G11: Unknown
A12: Ingest PDF church bulletin and extract facts | B12: Document Extraction - PDF | C12: Builder | D12: Select 'Upload files', drag and drop a 2 MB weekly church bulletin PDF containing service times and pastor bio, and click 'Read files'. | E12: Server parses PDF text streams, applies NLP regex patterns, extracts service times and staff items, and displays quotes referencing PDF filename. | G12: Unknown
A13: Ingest church flyer image via Vision AI OCR | B13: Multimodal Vision Extraction | C13: Builder | D13: Upload church flyer image (JPEG/PNG) displaying worship schedule and logo. | E13: Vision AI transcribes image text into machine-readable prose; rules parser extracts church schedule and logo reference. | G13: Unknown
... A21: Publish live production church without invite code | B21: Tenant Provisioning Guardrail | C21: Builder | D21: On preview screen, attempt to provision and deploy a new live church tenant without entering an invite code. | E21: System provisions new church tenant and deploys public domain. | G21: Unknown

Sheet Home
A1: Name of Test Case | B1: Category | C1: Name of Page | D1: Action to Take | E1: Expected Outcome | F1: Outcome/Result | G1: Pass/Fail
A2: Hero CTA: Find a place to serve button | B2: Navigation & User Flow | C2: Home | D2: Click 'Find a place to serve' primary button on the hero banner. | E2: Application navigates directly to '#/serve/find' volunteer matching page. | G2: Unknown
A3: Hero CTA: Planning your first visit button | B3: Navigation & User Flow | C3: Home | D3: Click 'Planning your first visit?' secondary button on the hero banner. | E3: Application navigates directly to '#/guests/plan' first-time guest page. | G3: Unknown
A4: Hero CTA: Ask Tekton chat launcher | B4: AI Assistant Integration | C4: Home | D4: Click 'Ask Tekton' button with chat icon in the hero banner. | E4: Sitewide chat assistant drawer slides open from right with greeting message. | G4: Unknown
A5: Serve feature card navigation | B5: Feature Card Routing | C5: Home | D5: Click 'Serve' feature card in the main features grid. | E5: Navigates to '#/serve' ministries directory overview page. | G5: Unknown
A6: Sermon Notes feature card navigation | B6: Feature Card Routing | C6: Home | D6: Click 'Sermon Notes' feature card in the main features grid. | E6: Navigates to '#/notes' sermon notes transcript archive. | G6: Unknown
A7: Give feature card goal progress bar display | B7: Fundraising Goal Tracking | C7: Home | D7: Inspect Give feature card when a church fund has an active fundraising goal. | E7: Card displays fund name, raised amount, goal amount, and accurately styled visual percentage progress bar. | G7: Unknown
A8: Get to know us directory quick button | B8: Quick Links Navigation | C8: Home | D8: Click 'Contact directory' button in the 'Get to know us' section. | E8: Navigates directly to '#/about/directory' staff contact listing. | G8: Unknown
A9: Service times and address card rendering | B9: Visitor Information | C9: Home | D9: Inspect 'Service times' block on the Home page. | E9: Displays weekly gathering schedule (e.g. 'Sunday 9:00 AM & 11:00 AM') and church physical address with location pin icon. | G9: Unknown
A10: Watch Live external link when livestream is unconfigured | B10: Livestream Integration | C10: Home | D10: Click 'Watch live' hero action button when church has no active livestream URL configured. | E10: Displays friendly popup indicating no active broadcast is currently streaming. | G10: Unknown
A11: Hero about text rendering on new unconfigured church | B11: Tenant Onboarding Display | C11: Home | D11: Open Home page for newly provisioned church with no about description provided. | E11: Displays elegant onboarding prompt guiding visitors and staff to add story. | G11: Unknown

Sheet Plan Your Visit
A1: Name of Test Case | B1: Category | C1: Name of Page | D1: Action to Take | E1: Expected Outcome | F1: Outcome/Result | G1: Pass/Fail
A2: Submit guest visit RSVP registration form | B2: Guest Registration Flow | C2: Guests - Plan Your Visit | D2: Fill in name 'Sarah Jenkins', contact 'sarah@example.org', select 'Sunday 9:00 AM', party size 3, and click 'Let us know you’re coming'. | E2: Form submits to POST /api/visits, receives visit token, saves token to localStorage, and updates UI to registered state. | G2: Unknown
A3: Validate required fields in visit registration | B3: Form Validation | C3: Guests - Plan Your Visit | D3: Leave name and contact fields blank and click 'Let us know you’re coming'. | E3: Browser displays HTML5 validation prompt on required name and contact inputs; submission is halted. | G3: Unknown
A4: Select service time from dynamic dropdown | B4: Form Interaction | C4: Guests - Plan Your Visit | D4: Click service time dropdown and select second gathering 'Sunday 11:00 AM'. | E4: Selected service time state updates and is included in the visit payload. | G4: Unknown
A5: Toggle 'I’d like someone to meet me' host checkbox | B5: Hospitality Preferences | C5: Guests - Plan Your Visit | D5: Uncheck the 'I’d like someone to meet me at the front doors' checkbox. | E5: wantsHost state sets to false; submitted visit payload reflects 'wants_host: false'. | G5: Unknown
A6: Click 'I’m on my way' arrival notification button | B6: Guest Arrival Flow | C6: Guests - Plan Your Visit | D6: On the confirmed visit card, click 'I’m on my way' button. | E6: Visits API updates status to 'on_the_way'; welcome team queue receives live status update. | G6: Unknown
A7: Click 'I have arrived' check-in button | B7: Guest Arrival Flow | C7: Guests - Plan Your Visit | D7: On confirmed visit card, click 'I have arrived' button. | E7: Visits API updates status to 'arrived'; triggers desktop notification on welcome team workstation. | G7: Unknown
A8: Expand FAQ accordion to read answer | B8: Content Disclosure | C8: Guests - Plan Your Visit | D8: Click on question 'What should I wear?' in the FAQ section. | E8: Accordion item expands revealing helpful answer about casual attire. | G8: Unknown
A9: Open Google Maps directions link | B9: External Navigation | C9: Guests - Plan Your Visit | D9: Click 'Get directions' button next to the church address. | E9: Opens Google Maps search query with church street address in new browser tab. | G9: Unknown
A10: Interactive parking spot selection on mobile Safari touchscreens | B10: Touchscreen Mapping | C10: Guests - Plan Your Visit | D10: Tap parking spot on campus SVG map using an iOS Safari mobile browser. | E10: Spot highlights and selection binds to form payload. | G10: Unknown
A11: Guest RSVP submission with international phone number format | B11: Input Sanitization & Regex | C11: Guests - Plan Your Visit | D11: Enter international format contact number '+44 20 7946 0958' in RSVP contact field. | E11: Validates international phone format and registers visit. | G11: Unknown

Sheet Welcome Team
A1: Name of Test Case | B1: Category | C1: Name of Page | D1: Action to Take | E1: Expected Outcome | F1: Outcome/Result | G1: Pass/Fail
A2: Block unauthorized visitor access to welcome queue | B2: Access Control | C2: Guests - Welcome Team | D2: Navigate to '#/guests/welcome' as an unauthenticated public visitor. | E2: Welcome queue is hidden; displays 'StaffOnly' notice prompting staff sign-in. | G2: Unknown
A3: Display arrived guests queue for signed-in staff | B3: Queue Visibility | C3: Guests - Welcome Team | D3: Sign in as staff and open '#/guests/welcome'. | E3: Displays WelcomeQueue component showing waiting list and planned guests list. | G3: Unknown
A4: Persist host staff name in local storage | B4: Host Identity | C4: Guests - Welcome Team | D4: Type host name 'Brother David' into 'Your name' field and reload page. | E4: Host name 'Brother David' is saved to localStorage and restored on reload. | G4: Unknown
A5: Claim an arrived guest from waiting queue | B5: Host Assignment | C5: Guests - Welcome Team | D5: Click 'I’ll meet them' button on a waiting guest card. | E5: Calls POST /visits/:id/claim with hostName; marks guest as claimed by Brother David. | G5: Unknown
A6: Dismiss welcomed guest from queue | B6: Status Lifecycle | C6: Guests - Welcome Team | D6: Click 'Welcomed' checkmark button on a claimed guest card. | E6: Calls PATCH /visits/:id with status 'welcomed'; removes guest from active waiting list. | G6: Unknown
A7: Display accurate party size and host preference tags | B7: Metadata Rendering | C7: Guests - Welcome Team | D7: Inspect waiting guest card for party of 4 who prefers not to be met. | E7: Card displays 'Party of 4' badge and muted notice 'Prefers not to be met at door'. | G7: Unknown
A8: Display elapsed waiting time counter | B8: Queue Metrics | C8: Guests - Welcome Team | D8: Observe waiting guest card for guest who arrived 6 minutes ago. | E8: Displays elapsed waiting counter 'Arrived 6m ago' updating periodically. | G8: Unknown
A9: Real-time queue polling updates without refresh | B9: Real-time Synchronization | C9: Guests - Welcome Team | D9: Keep Welcome Team screen open while a new guest checks in on another device. | E9: Background 5-second interval poll detects new arrival and adds card to queue with arrival chime/alert. | G9: Unknown
A10: Browser arrival push notifications on mobile browsers (iOS / Android) | B10: Web Push Notifications | C10: Guests - Welcome Team | D10: Tap 'Enable arrival notifications' on iOS Safari or mobile web browser. | E10: Native browser arrival push notifications fire when guest arrives. | G10: Unknown
A11: Concurrent guest claim race condition between two hosts | B11: Concurrency & Locking | C11: Guests - Welcome Team | D11: Two welcome hosts click 'I’ll meet them' on the same arrived guest card within 1 second. | E11: Optimistic concurrency lock notifies second host that guest was already claimed by another team member. | G11: Unknown

Sheet Serve
A1: Name of Test Case | B1: Category | C1: Name of Page | D1: Action to Take | E1: Expected Outcome | F1: Outcome/Result | G1: Pass/Fail
A2: Filter serving teams by keyword search | B2: Search & Filtering | C2: Serve | D2: Type 'worship' into ministry search input field. | E2: List filters instantly to ministries containing 'worship' in name, description, or category. | G2: Unknown
A3: Toggle 'Urgent needs only' filter checkbox | B3: Urgency Triage | C3: Serve | D3: Click 'Urgent needs only' filter button. | E3: Displays only ministries where unfilled volunteer slots are 35% or higher, with urgent badge. | G3: Unknown
A4: Expand ministry card to inspect team leader and roles | B4: Detail Disclosure | C4: Serve | D4: Click on 'Kids Ministry' card in the serving grid. | E4: Detailed drawer opens showing team description, time commitments, and ministry leader contact. | G4: Unknown
A5: Bookmark recommended ministry to saved shortlist | B5: Shortlist Management | C5: Serve | D5: Click 'Save to shortlist' bookmark icon on 'Worship Collective' recommendation card. | E5: Ministry is added to local saved list; navigation badge count increments by 1. | G5: Unknown
A6: View saved ministries tab | B6: Shortlist Review | C6: Serve | D6: Click 'Saved' sub-navigation tab ('#/serve/saved'). | E6: Displays all bookmarked serving opportunities with option to submit interest request. | G6: Unknown
A7: Staff view of filed volunteer connection requests | B7: Staff Queue Management | C7: Serve | D7: Sign in as staff and open '#/serve/saved' requests queue. | E7: Staff sees full list of member-submitted volunteer inquiries and chat connection requests. | G7: Unknown
A8: Staff approves volunteer connection request | B8: Workflow State Change | C8: Serve | D8: Click 'Connect' checkmark button on a pending volunteer request. | E8: Calls PATCH /requests/:id with status 'connected'; moves request to active connections list. | G8: Unknown
A9: Staff archives or deletes processed request | B9: Queue Cleanup | C9: Serve | D9: Click 'Remove' trash icon on an archived volunteer request. | E9: Calls DELETE /requests/:id; removes request card from staff queue view. | G9: Unknown
A10: AI volunteer matching with single-word generic input | B10: AI Recommendation Bounds | C10: Serve | D10: On volunteer finder, enter single word 'anything' into gifts input and click 'Find matching places'. | E10: Prompts user to specify gifts/skills or provides general serving opportunities. | G10: Unknown
A11: Real-time staff queue update across multiple browser sessions | B11: Cross-client Synchronization | C11: Serve | D11: Visitor files a volunteer request in chat; observe staff queue on a separate un-refreshed staff browser. | E11: Staff queue updates automatically via WebSocket or background push without manual reload. | G11: Unknown

Sheet Sermon Notes
A1: Name of Test Case | B1: Category | C1: Name of Page | D1: Action to Take | E1: Expected Outcome | F1: Outcome/Result | G1: Pass/Fail
A2: Browse sermon catalog and open message | B2: Content Discovery | C2: Sermon Notes | D2: Click on sermon card 'The Heart of the Father - Luke 15' in sermon list. | E2: Navigates to '#/notes/:id'; loads full sermon transcript, media player, and AI ask panel. | G2: Unknown
A3: Ask AI question about sermon content | B3: AI Sermon Q&A | C3: Sermon Notes | D3: In sermon ask box, type 'What did the pastor say about the older brother?' and click Ask. | E3: AI queries sermon embeddings, returns answer summarizing pastor's points, and quotes verbatim sentences with timestamps. | G3: Unknown
A4: Click transcript timestamp to seek media player | B4: Media Synchronization | C4: Sermon Notes | D4: Click timestamp link '[14:32]' inside sermon transcript text. | E4: Audio/video player seeks immediately to 14 minutes 32 seconds and starts playback. | G4: Unknown
A5: Toggle 'Bible quotes' highlight filter | B5: Transcript Annotation | C5: Sermon Notes | D5: Click 'Bible quotes' button in highlight categories toggle bar. | E5: All direct Scripture quotations in transcript highlight with gold background styling. | G5: Unknown
A6: Tap scripture highlight to open YouVersion verse card | B6: Scripture Integration | C6: Sermon Notes | D6: Click highlighted Bible reference 'Romans 8:28' in sermon transcript. | E6: VerseCard popover opens displaying full text of Romans 8:28 fetched from Bible API. | G6: Unknown
A7: Switch preferred Bible translation in reader preferences | B7: User Preferences | C7: Sermon Notes | D7: Open reader settings and change translation from NIV to ESV. | E7: Passage references reload with English Standard Version text; preference saved to localStorage. | G7: Unknown
A8: Adjust transcript font size for accessibility | B8: Accessibility & Display | C8: Sermon Notes | D8: Click font size '+' button in reader toolbar. | E8: Transcript body text size increases from 16px to 19px for enhanced readability. | G8: Unknown
A9: Staff creates new sermon note via YouTube URL | B9: Media Ingestion - YouTube | C9: Sermon Notes | D9: Sign in as staff, click '+ New note', enter valid YouTube link, title 'Sunday Service', and click 'Create note'. | E9: Backend queues YouTube audio download and Whisper transcription job; sermon status becomes 'queued'. | G9: Unknown
A10: Process sermon video with bot-protected YouTube URL | B10: Media Ingestion - YouTube | C10: Sermon Notes | D10: Submit a YouTube sermon URL that requires bot challenge or sign-in verification. | E10: System bypasses bot challenge and downloads audio for transcription. | G10: Unknown
A11: Upload video file exceeding 95 MB limit | B11: File Upload Validation | C11: Sermon Notes | D11: Attach 120 MB MP4 sermon recording and click 'Create note'. | E11: Client-side file validation prevents upload and shows clear file size guidance. | G11: Unknown

Sheet Calendar
A1: Name of Test Case | B1: Category | C1: Name of Page | D1: Action to Take | E1: Expected Outcome | F1: Outcome/Result | G1: Pass/Fail
A2: Toggle between monthly calendar grid and upcoming list view | B2: View Mode Switching | C2: Calendar | D2: Click 'List view' button in the calendar toolbar. | E2: Display changes from 7-day monthly grid to chronological list view grouped by date. | G2: Unknown
A3: Filter calendar events by category | B3: Category Filtering | C3: Calendar | D3: Click category filter button 'Youth & Kids'. | E3: Calendar highlights/shows only events tagged with 'Youth & Kids' category. | G3: Unknown
A4: Search calendar gatherings by keyword | B4: Keyword Search | C4: Calendar | D4: Type 'prayer' into calendar search bar. | E4: Filters calendar display to events containing 'prayer' in title or description. | G4: Unknown
A5: Navigate across calendar months | B5: Date Navigation | C5: Calendar | D5: Click 'Next month' arrow button in calendar header. | E5: Calendar advances to next month (e.g. November 2026); fetches and displays that month's events. | G5: Unknown
A6: Inspect event detail modal by clicking calendar cell | B6: Event Inspection | C6: Calendar | D6: Click on 'Community Outreach Day' event entry in the grid. | E6: Event detail modal opens showing date, time, location, host ministry, and full event description. | G6: Unknown
A7: Staff opens '+ Add event' modal and creates new event | B7: Event Creation | C7: Calendar | D7: Sign in as staff, click '+ Add event', fill in title 'Church Picnic', date, time, location, and click Save. | E7: Calls POST /events with event JSON; returns created event; reloads calendar with new item visible. | G7: Unknown
A8: Validate required fields in event creation form | B8: Form Validation | C8: Calendar | D8: In '+ Add event' modal, leave title empty and click Save. | E8: Form validation halts submission; highlights empty title field with required error. | G8: Unknown
A9: Staff deletes or cancels scheduled event | B9: Event Deletion | C9: Calendar | D9: Open event detail modal as staff and click 'Delete event' button with confirmation. | E9: Calls DELETE /events/:id; event is removed from calendar display. | G9: Unknown
A10: Automatic AI bulletin summary generation on event creation | B10: AI Content Generation | C10: Calendar | D10: As staff, create a new calendar event and check for automated AI bulletin summary. | E10: AI endpoint generates welcoming 2-sentence bulletin summary. | G10: Unknown
A11: Export calendar gatherings to Apple iCal / .ics file | B11: Calendar Standards Export | C11: Calendar | D11: Click 'Add to calendar' / export button on an event detail view. | E11: Downloads standardized .ics file for importing into Apple Calendar or Outlook. | G11: Unknown

Sheet Give
A1: Name of Test Case | B1: Category | C1: Name of Page | D1: Action to Take | E1: Expected Outcome | F1: Outcome/Result | G1: Pass/Fail
A2: Select preset donation amount button | B2: Donation Flow | C2: Give | D2: Click preset dollar amount button '$100'. | E2: Donation total updates to '$100.00' and highlights the $100 button. | G2: Unknown
A3: Enter custom donation dollar amount with validation | B3: Form Validation | C3: Give | D3: Click 'Custom amount' input, type '150.00', and proceed. | E3: Custom amount input accepts numeric value and sets donation total to $150.00. | G3: Unknown
A4: Select designated fund from fund selector dropdown | B4: Fund Allocation | C4: Give | D4: Open fund selector dropdown and choose 'Missions Fund'. | E4: Donation allocation updates to 'Missions Fund'; fund ID included in checkout session request. | G4: Unknown
A5: Browse active mission trips on Mission Trips tab | B5: Mission Trips Discovery | C5: Give | D5: Click 'Mission trips' tab ('#/give/trips'). | E5: Displays active mission trips with destination, trip dates, team size, and funding progress bar. | G5: Unknown
A6: Click 'Support this trip' to prefill donation fund | B6: Designated Trip Support | C6: Give | D6: Click 'Support this trip' button on Guatemala outreach card. | E6: Navigates to '#/give' with Guatemala mission fund pre-selected in fund dropdown. | G6: Unknown
A7: Submit volunteer application to join a mission trip | B7: Trip Volunteer Application | C7: Give | D7: Click 'Apply to go', fill in applicant name, email, skills, and submit application. | E7: Calls POST /trips/:id/apply; submits application for staff review; displays confirmation. | G7: Unknown
A8: Access monthly recurring gift management via secure token | B8: Subscription Self-Service | C8: Give | D8: Open manage gift link with valid token ('#/give/manage/:church.:token'). | E8: Loads donor's monthly gift details: amount, designated fund, next billing date, and cancellation action. | G8: Unknown
A9: Cancel recurring monthly donation | B9: Subscription Management | C9: Give | D9: On the manage recurring gift screen, click 'Cancel monthly gift' and confirm in prompt. | E9: Calls DELETE /giving/recurring; cancels Stripe subscription; displays cancellation confirmation. | G9: Unknown
A10: Direct credit card donation processing in Demo Mode | B10: Payment Processing | C10: Give | D10: Enter donation amount and attempt live credit card payment on demo church ('slug: demo'). | E10: Processes live donation via Stripe payment gateway. | G10: Unknown
A11: Monthly recurring donation setup without Stripe Connect | B11: Payment Configuration Prerequisite | C11: Give | D11: Attempt to set up monthly recurring donation on a church that has not connected Stripe. | E11: Monthly recurring option is disabled with clear prerequisite explanation. | G11: Unknown

Sheet Prayer Map
A1: Name of Test Case | B1: Category | C1: Name of Page | D1: Action to Take | E1: Expected Outcome | F1: Outcome/Result | G1: Pass/Fail
A2: Render interactive Leaflet world map with partner borders | B2: Map Visualization | C2: Prayer Map | D2: Navigate to '#/prayer'. | E2: Leaflet map initializes centered on global partner regions with highlighted country border polygons. | G2: Unknown
A3: Click country prayer beacon to inspect prayer focus | B3: Prayer Focus Inspection | C3: Prayer Map | D3: Click pulsing prayer beacon pin located on country 'Nepal'. | E3: Map centers on Nepal; 'prayer-detail' card below map populates with Nepal prayer needs and cultural context. | G3: Unknown
A4: Click real news pin to inspect verified headline and date | B4: News Pin Popup | C4: Prayer Map | D4: Click on red news pin marker located in Kenya. | E4: Popup appears displaying verified news headline, publication date, and summary. | G4: Unknown
A5: Verify sensitive nation security safeguard hides team coordinates | B5: Security & Anonymization | C5: Prayer Map | D5: Inspect prayer beacon for restricted/sensitive country. | E5: Pulsing beacon displays only country-level centroid; no local address, GPS coordinates, or missionary names are exposed. | G5: Unknown
A6: Verify compact labels toggle on dense zoom levels | B6: Label Collision Prevention | C6: Prayer Map | D6: Zoom out map to world overview level. | E6: LabelDensity hook detects potential label collisions and adds 'compact-labels' class to suppress overlapping text. | G6: Unknown
A7: Click 'Fit to borders' to re-center partner nations | B7: Map Bounds Ergonomics | C7: Prayer Map | D7: Pan map far off-center and refresh or trigger fit bounds. | E7: Map automatically calculates bounding box of all church mission regions and fits view with 40px padding. | G7: Unknown
A8: Filter prayer updates by selected country | B8: Geographic Filtering | C8: Prayer Map | D8: Select country 'Colombia' from partner nations list. | E8: News and prayer requests list below map filters exclusively to items matching Colombia country code. | G8: Unknown
A9: Smooth scroll to selected prayer detail card | B9: Interaction Ergonomics | C9: Prayer Map | D9: Click any country beacon on desktop viewport. | E9: Browser smoothly scrolls down to position 'prayer-detail' card into prominent view. | G9: Unknown
A10: Map rendering during backend API service outage | B10: Fault Resilience | C10: Prayer Map | D10: Disconnect backend API server and navigate to '#/prayer'. | E10: Map displays cached offline regions with retry option. | G10: Unknown
A11: Country beacon precision on small island nations | B11: Geographic Centroid Precision | C11: Prayer Map | D11: Inspect prayer beacon for small archipelagic partner nation (e.g. Fiji). | E11: Beacon pins directly to inhabited land territory. | G11: Unknown

Sheet About - Our Story
A1: Name of Test Case | B1: Category | C1: Name of Page | D1: Action to Take | E1: Expected Outcome | F1: Outcome/Result | G1: Pass/Fail
A2: Display church mission statement banner | B2: Mission Display | C2: About - Our Story | D2: Navigate to '#/about'. | E2: Displays 'Our mission' card featuring the church's core mission statement in prominent typography. | G2: Unknown
A3: Render church narrative story and history paragraphs | B3: Storytelling Content | C3: About - Our Story | D3: Inspect 'Our story' section on About page. | E3: Renders formatted narrative paragraphs detailing church founding, vision, and community impact. | G3: Unknown
A4: Inspect core values cards with distinct icons | B4: Core Values | C4: About - Our Story | D4: Inspect 'What we value' grid on About page. | E4: Displays core value cards (e.g. Grace, Community, Service, Scripture) each with distinct icon and description. | G4: Unknown
A5: Verify office hours and physical location in visit block | B5: Facility Details | C5: About - Our Story | D5: Inspect 'Find us / Come visit' section on About page. | E5: Displays church street address, office hours, and weekly gathering times. | G5: Unknown
A6: Click 'Plan your visit' CTA button | B6: Internal Navigation | C6: About - Our Story | D6: Click 'Plan your visit' primary button at bottom of story page. | E6: Navigates directly to '#/guests/plan' guest visit registration page. | G6: Unknown
A7: Click 'What we believe' button to navigate to beliefs tab | B7: Sub-navigation | C7: About - Our Story | D7: Click 'What we believe' secondary button. | E7: Navigates to '#/about/beliefs' statement of faith tab. | G7: Unknown
A8: Click 'Connect with us' button to navigate to connect tab | B8: Sub-navigation | C8: About - Our Story | D8: Click 'Connect with us' button. | E8: Navigates to '#/about/connect' next steps page. | G8: Unknown
A9: Hover sourced story text to verify import quote attribution | B9: Provenance Verification | C9: About - Our Story | D9: When previewing an imported church site, hover over imported About text. | E9: Sourced component tooltip appears displaying source URL and verbatim quote from imported website. | G9: Unknown
A10: Verify dynamic church name replacement across all story text | B10: Tenant Personalization | C10: About - Our Story | D10: View About page across two different tenant church configurations. | E10: Intro subtitle and story text dynamically replace placeholder with active church name. | G10: Unknown
A11: Provenance quote tooltip on mobile touchscreens | B11: Touchscreen Tooltip Ergonomics | C11: About - Our Story | D11: Tap sourced sentence on mobile phone to inspect provenance source and quote. | E11: Mobile modal or popover opens displaying quote attribution. | G11: Unknown

Sheet About - Beliefs
A1: Name of Test Case | B1: Category | C1: Name of Page | D1: Action to Take | E1: Expected Outcome | F1: Outcome/Result | G1: Pass/Fail
A2: Render statement of belief introductory preamble | B2: Doctrinal Overview | C2: About - Beliefs | D2: Navigate to '#/about/beliefs'. | E2: Displays preamble card: 'What we hold to' explaining the convictions that shape teaching and life together. | G2: Unknown
A3: Verify sequential two-digit numbering on belief articles | B3: Article Enumeration | C3: About - Beliefs | D3: Inspect numbered belief badges in the beliefs list. | E3: Belief items display clean two-digit index badges: '01', '02', '03' etc. | G3: Unknown
A4: Inspect Article 01 on Scripture and Inspiration | B4: Theological Content | C4: About - Beliefs | D4: Inspect belief item 01 'The Bible'. | E4: Displays doctrine affirming the authority, inspiration, and trustworthiness of the Scriptures. | G4: Unknown
A5: Inspect Article 02 on God and the Trinity | B5: Theological Content | C5: About - Beliefs | D5: Inspect belief item 02 'God'. | E5: Displays doctrine on God as Creator and eternally existing in three persons: Father, Son, and Holy Spirit. | G5: Unknown
A6: Inspect Article on Salvation by Grace through Faith | B6: Theological Content | C6: About - Beliefs | D6: Inspect belief item on 'Salvation'. | E6: Displays doctrine explaining salvation as a free gift received through faith in Jesus Christ alone. | G6: Unknown
A7: Render custom imported beliefs statement for imported site | B7: Custom Tenant Content | C7: About - Beliefs | D7: Open Beliefs page on church where Tekton imported custom doctrinal statement. | E7: ChurchBeliefs component renders the church's own imported doctrinal articles instead of sample data. | G7: Unknown
A8: Display demo church statement of faith fallback | B8: Demo Data Integrity | C8: About - Beliefs | D8: Open Beliefs page while viewing demo church tenant. | E8: Renders verified default beliefs dataset from data/beliefs.json. | G8: Unknown
A9: Sub-navigation tab switching to Our Story and Directory | B9: Sub-navigation | C9: About - Beliefs | D9: Click 'Our story' tab in sub-navigation bar. | E9: Switches view seamlessly back to '#/about' with active tab state updating. | G9: Unknown
A10: Semantic ordered list accessibility check (<ol>, <li>) | B10: Accessibility Standards | C10: About - Beliefs | D10: Inspect DOM structure of the beliefs listing. | E10: Belief items are structured inside semantic <ol class='beliefs'> and <li class='card belief'> elements for screen readers. | G10: Unknown
A11: Doctrinal beliefs display on imported site without statement of faith | B11: Conditional Routing | C11: About - Beliefs | D11: Open '#/about/beliefs' on church imported from a website with no beliefs page. | E11: Displays friendly notice explaining church has not published doctrinal beliefs. | G11: Unknown

Sheet About - News
A1: Name of Test Case | B1: Category | C1: Name of Page | D1: Action to Take | E1: Expected Outcome | F1: Outcome/Result | G1: Pass/Fail
A2: Filter news feed by kind: Updates vs Articles | B2: Content Filtering | C2: About - News | D2: Click 'Updates' filter toggle button. | E2: News feed filters to display only short announcement updates; longer articles are hidden. | G2: Unknown
